<?xml version = '1.0'?>
<robot xmlns:xacro = 'http://www.ros.org/wiki/xacro'>
    <!-- PROPERTIES -->
    <xacro:property name = 'a' value = '1.0'/>      <!-- scalar used for inertia -->
    <xacro:property name = 'd' value = '0.1'/>     <!-- scalar used for damping -->
    <xacro:property name = 'o' value = '0.000'/>    <!-- tuneable offset for wheel collision -->

    <material name = 'black'>
        <color rgba = '0.1 0.1 0.1 1'/>
    </material>

    <material name = 'green'>
        <color rgba = '0 0.7 0 1'/>
    </material>

    <material name = 'gray'>
        <color rgba = '0.83 0.83 0.83 1'/>
    </material>

    <!-- MACROS -->
    <xacro:macro name = 'cylinder_inertia' params = 'mass radius length'>
        <inertia
            ixx = '${a * mass * (3 * radius**2 + length**2) / 12}'
            ixy = '0'
            ixz = '0'
            iyy = '${a * mass * (3 * radius**2 + length**2) / 12}'
            iyz = '0'
            izz = '${a * mass * radius**2 / 12}'
        />
    </xacro:macro>

    <xacro:macro name = 'box_inertia' params = 'mass w h d'>
        <inertia
            ixx = '${a * mass * (h**2 + d**2) / 12}'
            ixy = '0'
            ixz = '0'
            iyy = '${a * mass * (w**2 + h**2) / 12}'
            iyz = '0'
            izz = '${a * mass * (w**2 + d**2) / 12}'
        />
    </xacro:macro>

    <!-- BASE LINK & CHASSIS LINK -->
    <!-- base link -->
    <link name = 'base_link'>
    </link>

    <!-- chassis link -->
    <link name = 'chassis_link'>
        <visual>
            <origin xyz = '0 0 0' rpy = '0 0 0'/>
            <geometry>
                <mesh filename = 'file://$(find sim_robot_description)/meshes/chassis.STL'/>
            </geometry>
            <material name = 'green'/>
        </visual>

        <collision>
            <origin xyz = '0.00475 0 0.004' rpy = '0 0 0'/>   <!-- collision box moved to match visual -->
            <geometry>
                <box size = '0.2235 0.139 0.1165'/>  
            </geometry>
        </collision>

        <inertial>
            <mass value = '2.415'/>
            <xacro:box_inertia
                mass = '2.415'
                w = '0.2235'
                h = '0.1165'
                d = '0.139'
            />
        </inertial>
    </link>

    <!-- chassis to base joint -->
    <joint name = 'base_joint' type = 'fixed'>
        <parent link = 'base_link'/>
        <child link = 'chassis_link'/>
        <origin xyz = '0 0 0.07115' rpy = '0 0 0'/> <!-- origin offset of 0.07115 -->
    </joint>

    <!-- WHEEL LINKS & JOINTS -->
    <!-- front right wheel link -->
    <link name = 'front_right_wheel_link'>
        <visual>
            <origin xyz = '0 0 0' rpy = '0 0 0'/>
            <geometry>
                <mesh filename = 'file://$(find sim_robot_description)/meshes/front_right_wheel.STL'/>
            </geometry>
            <material name = 'black'/>
        </visual>

        <collision>
            <origin xyz = '0 ${-1 * o} 0' rpy = '0 0 0'/>
            <geometry>
                <cylinder radius = '0.0325' length = '0.03035'/>
                <!-- <sphere radius = '0.0325'/> -->
            </geometry>
        </collision>

        <inertial>
            <mass value = '0.0575175'/>
            <xacro:cylinder_inertia
                mass = '0.0575175'
                radius = '0.0325'
                length = '0.03035'
            />
        </inertial>
    </link>

    <!-- front right wheel to chassis joint -->
    <joint name = 'front_right_joint' type = 'continuous'>
        <origin xyz = '0.08 -0.08475 -0.0389' rpy = '-1.5703 0 3.14159'/>
        <parent link = 'chassis_link'/>
        <child link = 'front_right_wheel_link'/>
        <axis xyz = '0 0 -1' rpy = '0 0 0'/>
        <dynamics damping = '${d}'/>
    </joint>

    <!-- front left wheel link -->
    <link name = 'front_left_wheel_link'>
        <visual>
            <origin xyz = '0 0 0' rpy = '0 0 0'/>
            <geometry>
                <mesh filename = 'file://$(find sim_robot_description)/meshes/front_left_wheel.STL'/>
            </geometry>
            <material name = 'black'/>
        </visual>

        <collision>
            <origin xyz = '0 ${o} 0' rpy = '0 0 0'/>
            <geometry>
                <cylinder radius = '0.0325' length = '0.03035'/>
                <!-- <sphere radius = '0.0325'/> -->
            </geometry>
        </collision>

        <inertial>
            <mass value = '0.0575175'/>
            <xacro:cylinder_inertia
                mass = '0.0575175'
                radius = '0.0325'
                length = '0.03035'
            />
        </inertial>
    </link>

    <!-- front left wheel to chassis joint -->
    <joint name = 'front_left_joint' type = 'continuous'>
        <origin xyz = '0.08 0.08475 -0.0389' rpy = '1.5703 0 0'/>
        <parent link = 'chassis_link'/>
        <child link = 'front_left_wheel_link'/>
        <axis xyz = '0 0 -1' rpy = '0 0 0'/>
        <dynamics damping = '${d}'/>
    </joint>

    <!-- back right wheel link -->
    <link name = 'back_right_wheel_link'>
        <visual>
            <origin xyz = '0 0 0' rpy = '0 0 0'/>
            <geometry>
                <mesh filename = 'file://$(find sim_robot_description)/meshes/back_right_wheel.STL'/>
            </geometry>
            <material name = 'black'/>
        </visual>

        <collision>
            <origin xyz = '0 ${-1 * o} 0' rpy = '0 0 0'/>
            <geometry>
                <cylinder radius = '0.0325' length = '0.03035'/>
                <!-- <sphere radius = '0.0325'/> -->
            </geometry>
        </collision>

        <inertial>
            <mass value = '0.0575175'/>
            <xacro:cylinder_inertia
                mass = '0.0575175'
                radius = '0.0325'
                length = '0.03035'
            />
        </inertial>
    </link>

    <!-- back right wheel to chassis joint -->
    <joint name = 'back_right_joint' type = 'continuous'>
        <origin xyz = '-0.08 -0.08475 -0.03946' rpy = '-1.57 0 3.14159'/>
        <parent link = 'chassis_link'/>
        <child link = 'back_right_wheel_link'/>
        <axis xyz = '0 0 -1' rpy = '0 0 0'/>
        <dynamics damping = '${d}'/>
    </joint>

    <!-- back left wheel link -->
    <link name = 'back_left_wheel_link'>
        <visual>
            <origin xyz = '0 0 0' rpy = '0 0 0'/>
            <geometry>
                <mesh filename = 'file://$(find sim_robot_description)/meshes/back_left_wheel.STL'/>
            </geometry>
            <material name = 'black'/>
        </visual>

        <collision>
            <origin xyz = '0 ${o} 0' rpy = '0 0 0'/>
            <geometry>
                <cylinder radius = '0.0325' length = '0.03035'/>
                <!-- <sphere radius = '0.0325'/> -->
            </geometry>
        </collision>

        <inertial>
            <mass value = '0.0575175'/>
            <xacro:cylinder_inertia
                mass = '0.0575175'
                radius = '0.0325'
                length = '0.03035'
            />
        </inertial>
    </link>

    <!-- back left wheel to chassis joint -->
    <joint name = 'back_left_joint' type = 'continuous'>
        <origin xyz = '-0.08 0.08475 -0.03954' rpy = '1.5703 0 0'/>
        <parent link = 'chassis_link'/>
        <child link = 'back_left_wheel_link'/>
        <axis xyz = '0 0 -1' rpy = '0 0 0'/>
        <dynamics damping = '${d}'/>
    </joint>
</robot>